<?xml version="1.0" ?>
<!-- =================================================================================== -->
<!-- |    This document was autogenerated by xacro from puma560_robot.urdf.xacro       | -->
<!-- |    EDITING THIS FILE BY HAND IS NOT RECOMMENDED                                 | -->
<!-- =================================================================================== -->
<robot name="Puma560">
  <material name="blue">
    <color rgba="0 0 0.8 0.8"/>
  </material>
  <material name="red">
    <color rgba="0.8 0 0 0.8"/>
  </material>
  <material name="green">
    <color rgba="0 0.8 0 0.8"/>
  </material>
  <link name="link1">
    <visual>
      <geometry>
        <mesh filename="package://puma560_description/meshes/puma_link1.stl" scale="0.0254 0.0254 0.0254"/>
      </geometry>
      <origin rpy="0 0 1.570796325"/>
      <material name="green"/>
    </visual>
    <!-- NOTE: Base link is static, so inertial properties are not strictly required for the simulation to run -->
  </link>
  <link name="link2">
    <visual>
      <geometry>
        <mesh filename="package://puma560_description/meshes/puma_link2.stl" scale="0.0254 0.0254 0.0254"/>
      </geometry>
      <origin rpy="0 0 0" xyz="0 0 -0.1"/>
      <material name="red"/>
    </visual>
    <!-- ADDED FOR PHYSICS SIMULATION -->
    <inertial>
      <origin rpy="0 0 0" xyz="0 0 0"/>
      <mass value="17.0"/>
      <!-- Approx. mass in kg -->
      <inertia ixx="0.35" ixy="0" ixz="0" iyy="0.35" iyz="0" izz="0.1"/>
    </inertial>
  </link>
  <joint name="j1" type="revolute">
    <parent link="link1"/>
    <child link="link2"/>
    <origin rpy="1.570796325 0 0" xyz="0 0 0.6718"/>
    <axis xyz="0 1 0"/>
    <limit effort="1000.0" lower="-3.14159265" upper="3.14159265" velocity="0"/>
  </joint>
  <link name="link3">
    <visual>
      <geometry>
        <mesh filename="package://puma560_description/meshes/puma_link3.stl" scale="0.0254 0.0254 0.0254"/>
      </geometry>
      <origin xyz="0 0 0.1936"/>
      <material name="blue"/>
    </visual>
    <!-- ADDED FOR PHYSICS SIMULATION -->
    <inertial>
      <origin rpy="0 0 0" xyz="0 0 0"/>
      <mass value="5.0"/>
      <!-- Approx. mass in kg -->
      <inertia ixx="0.1" ixy="0" ixz="0" iyy="0.1" iyz="0" izz="0.05"/>
    </inertial>
  </link>
  <joint name="j2" type="revolute">
    <parent link="link2"/>
    <child link="link3"/>
    <origin rpy="0 0 0" xyz="0 0 0"/>
    <axis xyz="0 0 1"/>
    <limit effort="1000.0" lower="-1.570796325" upper="1.570796325" velocity="0"/>
  </joint>
  <link name="link4">
    <visual>
      <geometry>
        <mesh filename="package://puma560_description/meshes/puma_link4.stl" scale="0.0254 0.0254 0.0254"/>
      </geometry>
      <origin rpy="0 0 0" xyz="0 0 0"/>
      <material name="green"/>
    </visual>
    <!-- ADDED FOR PHYSICS SIMULATION -->
    <inertial>
      <origin rpy="0 0 0" xyz="0 0 0"/>
      <mass value="2.0"/>
      <!-- Approx. mass in kg -->
      <inertia ixx="0.05" ixy="0" ixz="0" iyy="0.05" iyz="0" izz="0.05"/>
    </inertial>
  </link>
  <joint name="j3" type="revolute">
    <parent link="link3"/>
    <child link="link4"/>
    <origin rpy="0 0 -1.570796325" xyz="0.4318 -0.0203 0.1501"/>
    <axis xyz="0 0 1"/>
    <limit effort="1000.0" lower="-1.570796325" upper="1.570796325" velocity="0"/>
  </joint>
  <link name="link5">
    <visual>
      <geometry>
        <mesh filename="package://puma560_description/meshes/puma_link5.stl" scale="0.0254 0.0254 0.0254"/>
      </geometry>
      <origin rpy="0 0 1.570796325" xyz="0 0 0.3621"/>
      <material name="red"/>
    </visual>
    <!-- ADDED FOR PHYSICS SIMULATION -->
    <inertial>
      <origin rpy="0 0 0" xyz="0 0 0"/>
      <mass value="1.0"/>
      <!-- Approx. mass in kg -->
      <inertia ixx="0.02" ixy="0" ixz="0" iyy="0.02" iyz="0" izz="0.02"/>
    </inertial>
  </link>
  <joint name="j4" type="revolute">
    <parent link="link4"/>
    <child link="link5"/>
    <origin rpy="1.570796325 0 1.570796325" xyz="0 0 0"/>
    <axis xyz="0 0 1"/>
    <limit effort="1000.0" lower="-1.570796325" upper="1.570796325" velocity="0"/>
  </joint>
  <link name="link6">
    <visual>
      <geometry>
        <mesh filename="package://puma560_description/meshes/puma_link6.stl" scale="0.0254 0.0254 0.0254"/>
      </geometry>
      <origin rpy="3.14159265 0 1.570796325" xyz="0 0 0"/>
      <material name="green"/>
    </visual>
    <!-- ADDED FOR PHYSICS SIMULATION -->
    <inertial>
      <origin rpy="0 0 0" xyz="0 0 0"/>
      <mass value="1.0"/>
      <!-- Approx. mass in kg -->
      <inertia ixx="0.02" ixy="0" ixz="0" iyy="0.02" iyz="0" izz="0.02"/>
    </inertial>
  </link>
  <joint name="j5" type="revolute">
    <parent link="link5"/>
    <child link="link6"/>
    <origin rpy="1.570796325 0 0" xyz="0 0 0.4331"/>
    <axis xyz="0 0 1"/>
    <limit effort="1000.0" lower="-1.570796325" upper="1.570796325" velocity="0"/>
  </joint>
  <link name="link7">
    <visual>
      <geometry>
        <mesh filename="package://puma560_description/meshes/puma_link7.stl" scale="0.0254 0.0254 0.0254"/>
      </geometry>
      <origin rpy="0 0 0" xyz="0 0 -0.010"/>
      <material name="blue"/>
    </visual>
    <!-- ADDED FOR PHYSICS SIMULATION -->
    <inertial>
      <origin rpy="0 0 0" xyz="0 0 0"/>
      <mass value="0.5"/>
      <!-- Approx. mass in kg for the end-effector mount -->
      <inertia ixx="0.01" ixy="0" ixz="0" iyy="0.01" iyz="0" izz="0.01"/>
    </inertial>
  </link>
  <joint name="j6" type="revolute">
    <parent link="link6"/>
    <child link="link7"/>
    <origin rpy="-1.570796325 0 0" xyz="0 0.0558 0"/>
    <axis xyz="0 0 1"/>
    <limit effort="1000.0" lower="-1.570796325" upper="1.570796325" velocity="0"/>
  </joint>
  <!-- ... (all your existing link and joint definitions) ... -->
  <!-- ========================================================== -->
  <!-- |           TRANSMISSIONS (ACTUATORS)                    | -->
  <!-- ========================================================== -->
  <!-- These tags tell the simulator that the joints are motorized -->
  <transmission name="tran1">
    <type>hardware_interface/PositionJointInterface</type>
    <joint name="j1"/>
    <hardwareInterface>hardware_interface/PositionJointInterface</hardwareInterface>
  </transmission>
  <transmission name="tran2">
    <type>hardware_interface/PositionJointInterface</type>
    <joint name="j2"/>
    <hardwareInterface>hardware_interface/PositionJointInterface</hardwareInterface>
  </transmission>
  <transmission name="tran3">
    <type>hardware_interface/PositionJointInterface</type>
    <joint name="j3"/>
    <hardwareInterface>hardware_interface/PositionJointInterface</hardwareInterface>
  </transmission>
  <transmission name="tran4">
    <type>hardware_interface/PositionJointInterface</type>
    <joint name="j4"/>
    <hardwareInterface>hardware_interface/PositionJointInterface</hardwareInterface>
  </transmission>
  <transmission name="tran5">
    <type>hardware_interface/PositionJointInterface</type>
    <joint name="j5"/>
    <hardwareInterface>hardware_interface/PositionJointInterface</hardwareInterface>
  </transmission>
  <transmission name="tran6">
    <type>hardware_interface/PositionJointInterface</type>
    <joint name="j6"/>
    <hardwareInterface>hardware_interface/PositionJointInterface</hardwareInterface>
  </transmission>
</robot>
